Workbook

Sheet Calculadora
B2: Calculadora de um triângulo
B4: Preencha somente as células amarelas. | G4: As respostas são calculadas automaticamente.
B6: Pontos do triângulo | G6: M — transformações do objeto
B7: Vértice | C7: x | D7: y | E7: z | G7: =IF(Matrizes!$C$107<>"OK","—",Matrizes!B67) -> 1 | H7: =IF(Matrizes!$C$107<>"OK","—",Matrizes!C67) -> -1.7320508 | I7: =IF(Matrizes!$C$107<>"OK","—",Matrizes!D67) -> 0 | J7: =IF(Matrizes!$C$107<>"OK","—",Matrizes!E67) -> 5.1961524
B8: A | C8: -2.5 | D8: -2.5 | E8: 2 | G8: =IF(Matrizes!$C$107<>"OK","—",Matrizes!B68) -> 1.7320508 | H8: =IF(Matrizes!$C$107<>"OK","—",Matrizes!C68) -> 1 | I8: =IF(Matrizes!$C$107<>"OK","—",Matrizes!D68) -> 0 | J8: =IF(Matrizes!$C$107<>"OK","—",Matrizes!E68) -> -0.57735027
B9: B | C9: 6 | D9: 9 | E9: 2 | G9: =IF(Matrizes!$C$107<>"OK","—",Matrizes!B69) -> 0 | H9: =IF(Matrizes!$C$107<>"OK","—",Matrizes!C69) -> 0 | I9: =IF(Matrizes!$C$107<>"OK","—",Matrizes!D69) -> 2 | J9: =IF(Matrizes!$C$107<>"OK","—",Matrizes!E69) -> -2
B10: C | C10: -2.5 | D10: 2.5 | E10: 2 | G10: =IF(Matrizes!$C$107<>"OK","—",Matrizes!B70) -> 0 | H10: =IF(Matrizes!$C$107<>"OK","—",Matrizes!C70) -> 0 | I10: =IF(Matrizes!$C$107<>"OK","—",Matrizes!D70) -> 0 | J10: =IF(Matrizes!$C$107<>"OK","—",Matrizes!E70) -> 1
B12: Rotação | G12: MVP — matriz final com câmera
B13: Eixo | C13: Z | G13: =IF(Matrizes!$C$107<>"OK","—",Matrizes!B101) -> -0.45612273 | H13: =IF(Matrizes!$C$107<>"OK","—",Matrizes!C101) -> 0.79002774 | I13: =IF(Matrizes!$C$107<>"OK","—",Matrizes!D101) -> -2.4326546 | J13: =IF(Matrizes!$C$107<>"OK","—",Matrizes!E101) -> 2.6472668
B14: Ângulo em graus | C14: 60 | G14: =IF(Matrizes!$C$107<>"OK","—",Matrizes!B102) -> -1.3207949 | H14: =IF(Matrizes!$C$107<>"OK","—",Matrizes!C102) -> 2.964824 | I14: =IF(Matrizes!$C$107<>"OK","—",Matrizes!D102) -> 1.2105039 | J14: =IF(Matrizes!$C$107<>"OK","—",Matrizes!E102) -> -10.875215
B15: Em relação à | C15: Centro | G15: =IF(Matrizes!$C$107<>"OK","—",Matrizes!B103) -> -1.9665447 | H15: =IF(Matrizes!$C$107<>"OK","—",Matrizes!C103) -> -0.90643128 | I15: =IF(Matrizes!$C$107<>"OK","—",Matrizes!D103) -> 0.074354942 | J15: =IF(Matrizes!$C$107<>"OK","—",Matrizes!E103) -> 32.710569
B16: Não pediu rotação? Deixe o eixo em Nenhuma. | G16: =IF(Matrizes!$C$107<>"OK","—",Matrizes!B104) -> -1.815272 | H16: =IF(Matrizes!$C$107<>"OK","—",Matrizes!C104) -> -0.83670579 | I16: =IF(Matrizes!$C$107<>"OK","—",Matrizes!D104) -> 0.068635331 | J16: =IF(Matrizes!$C$107<>"OK","—",Matrizes!E104) -> 32.117449
B18: Escala | G18: Pontos finais no mundo
B19: Fator | C19: 2 | G19: A | H19: B | I19: C
B20: Em relação à | C20: Centro | G20: =IF(Matrizes!$C$107<>"OK","—",Matrizes!G67) -> 7.0262794 | H20: =IF(Matrizes!$C$107<>"OK","—",Matrizes!H67) -> -4.3923048 | I20: =IF(Matrizes!$C$107<>"OK","—",Matrizes!I67) -> -1.6339746 | J20: x
B21: 1 = sem mudança | 2 = dobro | 0,5 = metade | G21: =IF(Matrizes!$C$107<>"OK","—",Matrizes!G68) -> -7.4074773 | H21: =IF(Matrizes!$C$107<>"OK","—",Matrizes!H68) -> 18.814955 | I21: =IF(Matrizes!$C$107<>"OK","—",Matrizes!I68) -> -2.4074773 | J21: y
G22: =IF(Matrizes!$C$107<>"OK","—",Matrizes!G69) -> 2 | H22: =IF(Matrizes!$C$107<>"OK","—",Matrizes!H69) -> 2 | I22: =IF(Matrizes!$C$107<>"OK","—",Matrizes!I69) -> 2 | J22: z
B23: Deslocamento | G23: =IF(Matrizes!$C$107<>"OK","—",Matrizes!G70) -> 1 | H23: =IF(Matrizes!$C$107<>"OK","—",Matrizes!H70) -> 1 | I23: =IF(Matrizes!$C$107<>"OK","—",Matrizes!I70) -> 1 | J23: w
C24: x | D24: y | E24: z
B25: Somar às coordenadas | C25: 0 | D25: 0 | E25: 0 | G25: Pontos normalizados em W
B26: Não pediu deslocamento? Deixe os três valores em 0. | G26: A | H26: B | I26: C
G27: =IF(Matrizes!$C$107<>"OK","—",IF(Matrizes!G104=0,"W = 0",Matrizes!G101/IF(Matrizes!G104=0,1,Matrizes!G104))) -> -0.078509226 | H27: =IF(Matrizes!$C$107<>"OK","—",IF(Matrizes!H104=0,"W = 0",Matrizes!H101/IF(Matrizes!H104=0,1,Matrizes!H104))) -> 0.15582392 | I27: =IF(Matrizes!$C$107<>"OK","—",IF(Matrizes!I104=0,"W = 0",Matrizes!I101/IF(Matrizes!I104=0,1,Matrizes!I104))) -> 0.02585892 | J27: x
B28: Câmera | G28: =IF(Matrizes!$C$107<>"OK","—",IF(Matrizes!G104=0,"W = 0",Matrizes!G102/IF(Matrizes!G104=0,1,Matrizes!G104))) -> -0.32311658 | H28: =IF(Matrizes!$C$107<>"OK","—",IF(Matrizes!H104=0,"W = 0",Matrizes!H102/IF(Matrizes!H104=0,1,Matrizes!H104))) -> 0.74493147 | I28: =IF(Matrizes!$C$107<>"OK","—",IF(Matrizes!I104=0,"W = 0",Matrizes!I102/IF(Matrizes!I104=0,1,Matrizes!I104))) -> 0.065122949 | J28: y
C29: x | D29: y | E29: z | G29: =IF(Matrizes!$C$107<>"OK","—",IF(Matrizes!G104=0,"W = 0",Matrizes!G103/IF(Matrizes!G104=0,1,Matrizes!G104))) -> 1.0297561 | H29: =IF(Matrizes!$C$107<>"OK","—",IF(Matrizes!H104=0,"W = 0",Matrizes!H103/IF(Matrizes!H104=0,1,Matrizes!H104))) -> 0.93272441 | I29: =IF(Matrizes!$C$107<>"OK","—",IF(Matrizes!I104=0,"W = 0",Matrizes!I103/IF(Matrizes!I104=0,1,Matrizes!I104))) -> 1.0232969 | J29: z
B30: Posição do olho | C30: 3 | D30: 32 | E30: 1 | G30: =IF(Matrizes!$C$107<>"OK","—",IF(Matrizes!G104=0,"W = 0",Matrizes!G104/IF(Matrizes!G104=0,1,Matrizes!G104))) -> 1 | H30: =IF(Matrizes!$C$107<>"OK","—",IF(Matrizes!H104=0,"W = 0",Matrizes!H104/IF(Matrizes!H104=0,1,Matrizes!H104))) -> 1 | I30: =IF(Matrizes!$C$107<>"OK","—",IF(Matrizes!I104=0,"W = 0",Matrizes!I104/IF(Matrizes!I104=0,1,Matrizes!I104))) -> 1 | J30: w
B31: Apontar para (target) | C31: Centro
B32: Target, se Manual | C32: 0 | D32: 0 | E32: 0
B33: Up vector | C33: 0 | D33: 1 | E33: 0 | G33: Visibilidade | K33: =HYPERLINK("#'Detalhes'!B2","ℹ") -> ℹ
B34: Centro = centro final do triângulo. Preencha o target manual somente se escolher Manual. | G34: =Matrizes!C123 -> Parcialmente no volume
B36: Projeção
B37: FOV em graus | C37: 60 | D37: Tipo | E37: Vertical | G37: Dentro: todo o triângulo no volume da câmera. Parcialmente: apenas uma parte. Fora: não aparece. Oclusão por outro objeto não é calculada.
B38: Largura da janela | C38: 800 | D38: Altura | E38: 600
B39: Near | C39: 1 | D39: Far | E39: 25
B40: Use os dados da câmera e da janela do enunciado. Se o FOV não disser horizontal ou vertical, confirme a convenção.
G41: Se precisar apresentar as contas, a aba Matrizes mostra rotação, escala, deslocamento, View, Projection e os produtos intermediários. A configuração continua toda nesta aba.
B43: Ordem usada: rotação, escala e deslocamento. Centro mantém o próprio centro fixo durante a transformação; Origem usa (0,0,0).

Sheet Matrizes
B2: Matrizes intermediárias
B4: Preenchimento pela aba Calculadora. Vetores-coluna; projeção OpenGL.
B6: Pontos iniciais | G6: Centro inicial
B7: A | C7: B | D7: C
B8: =Calculadora!C8 -> -2.5 | C8: =Calculadora!C9 -> 6 | D8: =Calculadora!C10 -> -2.5 | G8: =SUM(B8:D8)/3 -> 0.33333333
B9: =Calculadora!D8 -> -2.5 | C9: =Calculadora!D9 -> 9 | D9: =Calculadora!D10 -> 2.5 | G9: =SUM(B9:D9)/3 -> 3
B10: =Calculadora!E8 -> 2 | C10: =Calculadora!E9 -> 2 | D10: =Calculadora!E10 -> 2 | G10: =SUM(B10:D10)/3 -> 2
B11: =1 -> 1 | C11: =1 -> 1 | D11: =1 -> 1 | G11: =1 -> 1
B14: R — rotação na origem | G14: Pivô da rotação
B15: =IF(Calculadora!$C$13="Nenhuma",1,IF(Calculadora!$C$13="X",1,IF(Calculadora!$C$13="Y",COS(Calculadora!$C$14*PI()/180),COS(Calculadora!$C$14*PI()/180)))) -> 0.5 | C15: =IF(Calculadora!$C$13="Nenhuma",0,IF(Calculadora!$C$13="X",0,IF(Calculadora!$C$13="Y",0,-SIN(Calculadora!$C$14*PI()/180)))) -> -0.8660254 | D15: =IF(Calculadora!$C$13="Nenhuma",0,IF(Calculadora!$C$13="X",0,IF(Calculadora!$C$13="Y",SIN(Calculadora!$C$14*PI()/180),0))) -> 0 | E15: =0 -> 0 | G15: =IF(Calculadora!C15="Centro",G8,0) -> 0.33333333
B16: =IF(Calculadora!$C$13="Nenhuma",0,IF(Calculadora!$C$13="X",0,IF(Calculadora!$C$13="Y",0,SIN(Calculadora!$C$14*PI()/180)))) -> 0.8660254 | C16: =IF(Calculadora!$C$13="Nenhuma",1,IF(Calculadora!$C$13="X",COS(Calculadora!$C$14*PI()/180),IF(Calculadora!$C$13="Y",1,COS(Calculadora!$C$14*PI()/180)))) -> 0.5 | D16: =IF(Calculadora!$C$13="Nenhuma",0,IF(Calculadora!$C$13="X",-SIN(Calculadora!$C$14*PI()/180),IF(Calculadora!$C$13="Y",0,0))) -> 0 | E16: =0 -> 0 | G16: =IF(Calculadora!C15="Centro",G9,0) -> 3
B17: =IF(Calculadora!$C$13="Nenhuma",0,IF(Calculadora!$C$13="X",0,IF(Calculadora!$C$13="Y",-SIN(Calculadora!$C$14*PI()/180),0))) -> 0 | C17: =IF(Calculadora!$C$13="Nenhuma",0,IF(Calculadora!$C$13="X",SIN(Calculadora!$C$14*PI()/180),IF(Calculadora!$C$13="Y",0,0))) -> 0 | D17: =IF(Calculadora!$C$13="Nenhuma",1,IF(Calculadora!$C$13="X",COS(Calculadora!$C$14*PI()/180),IF(Calculadora!$C$13="Y",COS(Calculadora!$C$14*PI()/180),1))) -> 1 | E17: =0 -> 0 | G17: =IF(Calculadora!C15="Centro",G10,0) -> 2
B18: =0 -> 0 | C18: =0 -> 0 | D18: =0 -> 0 | E18: =1 -> 1
B21: T(−centro da rotação) | G21: T(+centro da rotação)
B22: =1 -> 1 | C22: =0 -> 0 | D22: =0 -> 0 | E22: =-1*G15 -> -0.33333333 | G22: =1 -> 1 | H22: =0 -> 0 | I22: =0 -> 0 | J22: =1*G15 -> 0.33333333
B23: =0 -> 0 | C23: =1 -> 1 | D23: =0 -> 0 | E23: =-1*G16 -> -3 | G23: =0 -> 0 | H23: =1 -> 1 | I23: =0 -> 0 | J23: =1*G16 -> 3
B24: =0 -> 0 | C24: =0 -> 0 | D24: =1 -> 1 | E24: =-1*G17 -> -2 | G24: =0 -> 0 | H24: =0 -> 0 | I24: =1 -> 1 | J24: =1*G17 -> 2
B25: =0 -> 0 | C25: =0 -> 0 | D25: =0 -> 0 | E25: =1 -> 1 | G25: =0 -> 0 | H25: =0 -> 0 | I25: =0 -> 0 | J25: =1 -> 1
B28: MR — rotação com pivô | G28: Pontos após rotação
B29: =B15 -> 0.5 | C29: =C15 -> -0.8660254 | D29: =D15 -> 0 | E29: =G15-B15*G15-C15*G16-D15*G17 -> 2.7647429 | G29: =B29*B8+C29*B9+D29*B10+E29*B11 -> 3.6798064 | H29: =B29*C8+C29*C9+D29*C10+E29*C11 -> -2.0294858 | I29: =B29*D8+C29*D9+D29*D10+E29*D11 -> -0.65032063
B30: =B16 -> 0.8660254 | C30: =C16 -> 0.5 | D30: =D16 -> 0 | E30: =G16-B16*G15-C16*G16-D16*G17 -> 1.2113249 | G30: =B30*B8+C30*B9+D30*B10+E30*B11 -> -2.2037386 | H30: =B30*C8+C30*C9+D30*C10+E30*C11 -> 10.907477 | I30: =B30*D8+C30*D9+D30*D10+E30*D11 -> 0.29626136
B31: =B17 -> 0 | C31: =C17 -> 0 | D31: =D17 -> 1 | E31: =G17-B17*G15-C17*G16-D17*G17 -> 0 | G31: =B31*B8+C31*B9+D31*B10+E31*B11 -> 2 | H31: =B31*C8+C31*C9+D31*C10+E31*C11 -> 2 | I31: =B31*D8+C31*D9+D31*D10+E31*D11 -> 2
B32: =0 -> 0 | C32: =0 -> 0 | D32: =0 -> 0 | E32: =1 -> 1 | G32: =B32*B8+C32*B9+D32*B10+E32*B11 -> 1 | H32: =B32*C8+C32*C9+D32*C10+E32*C11 -> 1 | I32: =B32*D8+C32*D9+D32*D10+E32*D11 -> 1
G35: Centro após rotação
G36: =SUM(G29:I29)/3 -> 0.33333333 | H36: =SUM(G30:I30)/3 -> 3 | I36: =SUM(G31:I31)/3 -> 2
B38: S — escala na origem | G38: Pivô da escala
B39: =Calculadora!C19 -> 2 | C39: =0 -> 0 | D39: =0 -> 0 | E39: =0 -> 0 | G39: =IF(Calculadora!C20="Centro",G36,0) -> 0.33333333
B40: =0 -> 0 | C40: =Calculadora!C19 -> 2 | D40: =0 -> 0 | E40: =0 -> 0 | G40: =IF(Calculadora!C20="Centro",H36,0) -> 3
B41: =0 -> 0 | C41: =0 -> 0 | D41: =Calculadora!C19 -> 2 | E41: =0 -> 0 | G41: =IF(Calculadora!C20="Centro",I36,0) -> 2
B42: =0 -> 0 | C42: =0 -> 0 | D42: =0 -> 0 | E42: =1 -> 1
B45: T(−centro da escala) | G45: T(+centro da escala)
B46: =1 -> 1 | C46: =0 -> 0 | D46: =0 -> 0 | E46: =-1*G39 -> -0.33333333 | G46: =1 -> 1 | H46: =0 -> 0 | I46: =0 -> 0 | J46: =1*G39 -> 0.33333333
B47: =0 -> 0 | C47: =1 -> 1 | D47: =0 -> 0 | E47: =-1*G40 -> -3 | G47: =0 -> 0 | H47: =1 -> 1 | I47: =0 -> 0 | J47: =1*G40 -> 3
B48: =0 -> 0 | C48: =0 -> 0 | D48: =1 -> 1 | E48: =-1*G41 -> -2 | G48: =0 -> 0 | H48: =0 -> 0 | I48: =1 -> 1 | J48: =1*G41 -> 2
B49: =0 -> 0 | C49: =0 -> 0 | D49: =0 -> 0 | E49: =1 -> 1 | G49: =0 -> 0 | H49: =0 -> 0 | I49: =0 -> 0 | J49: =1 -> 1
B52: MS — escala com pivô | G52: Pontos após escala
B53: =B39 -> 2 | C53: =C39 -> 0 | D53: =D39 -> 0 | E53: =G39*(1-Calculadora!C19) -> -0.33333333 | G53: =B53*G29+C53*G30+D53*G31+E53*G32 -> 7.0262794 | H53: =B53*H29+C53*H30+D53*H31+E53*H32 -> -4.3923048 | I53: =B53*I29+C53*I30+D53*I31+E53*I32 -> -1.6339746
B54: =B40 -> 0 | C54: =C40 -> 2 | D54: =D40 -> 0 | E54: =G40*(1-Calculadora!C19) -> -3 | G54: =B54*G29+C54*G30+D54*G31+E54*G32 -> -7.4074773 | H54: =B54*H29+C54*H30+D54*H31+E54*H32 -> 18.814955 | I54: =B54*I29+C54*I30+D54*I31+E54*I32 -> -2.4074773
B55: =B41 -> 0 | C55: =C41 -> 0 | D55: =D41 -> 2 | E55: =G41*(1-Calculadora!C19) -> -2 | G55: =B55*G29+C55*G30+D55*G31+E55*G32 -> 2 | H55: =B55*H29+C55*H30+D55*H31+E55*H32 -> 2 | I55: =B55*I29+C55*I30+D55*I31+E55*I32 -> 2
B56: =0 -> 0 | C56: =0 -> 0 | D56: =0 -> 0 | E56: =1 -> 1 | G56: =B56*G29+C56*G30+D56*G31+E56*G32 -> 1 | H56: =B56*H29+C56*H30+D56*H31+E56*H32 -> 1 | I56: =B56*I29+C56*I30+D56*I31+E56*I32 -> 1
...

Sheet Detalhes
B2: Por que essa visibilidade?
B4: =HYPERLINK("#'Calculadora'!G33","Voltar à calculadora") -> Voltar à calculadora
B6: =Calculadora!G34 -> Parcialmente no volume
B8: =IF(Matrizes!$C$107<>"OK","Preencha os dados válidos para ver a explicação. "&Matrizes!C107,IF(B6="Dentro do volume","O triângulo inteiro está dentro dos seis limites da câmera. Ele cabe no enquadramento e fica entre o Near e o Far.",IF(B6="Parcialmente no volume","Uma parte do triângulo está dentro e será mantida; a parte que ultrapassa os limites será cortada. Há vértices fora nestas direções: "&IF(G15>0,"esquerda; ","")&IF(G16>0,"direita; ","")&IF(G17>0,"abaixo; ","")&IF(G18>0,"acima; ","")&IF(G19>0,"antes do Near; ","")&IF(G20>0,"além do Far; ","")&"Veja quais vértices na tabela.",IF(MAX(Matrizes!G104:I104)<=0,"O triângulo inteiro está atrás da câmera ou no plano do olho. A câmera olha para o outro lado; por isso, ele não aparece.",IF(G20=3,"O triângulo inteiro ultrapassou o Far = "&Calculadora!E39&". O Z normalizado deveria ser no máximo 1, mas ficou A = "&ROUND(D20,6)&", B = "&ROUND(E20,6)&" e C = "&ROUND(F20,6)&". Como os três valores são maiores que 1, o triângulo inteiro fica fora do volume.",IF(G19=3,"O triângulo inteiro está antes do Near = "&Calculadora!C39&". As profundidades são "&"A = "&ROUND(Matrizes!G104,3)&", B = "&ROUND(Matrizes!H104,3)&" e C = "&ROUND(Matrizes!I104,3)&". Os três valores ficam abaixo do mínimo; por isso, nenhuma parte do triângulo aparece.",IF(MAX(G15:G20)=3,"O triângulo inteiro está fora do enquadramento: os três vértices ficam "&IF(G15=3,"esquerda; ","")&IF(G16=3,"direita; ","")&IF(G17=3,"abaixo; ","")&IF(G18=3,"acima; ","")&IF(G19=3,"antes do Near; ","")&IF(G20=3,"além do Far; ","")&"Nenhuma parte permanece dentro da área vista pela câmera.","O triângulo passa por fora do volume da câmera. Mesmo testando suas arestas e seu interior, nenhuma parte fica dentro dos seis limites ao mesmo tempo."))))))) -> Uma parte do triângulo está dentro e será mantida; a parte que ultrapassa os limites será cortada. Há vértices fora nestas direções: além do Far; Veja quais vértices na tabela.
B13: =IF(Matrizes!$C$107<>"OK","Aguardando dados.",IF(MIN(Matrizes!G104:I104)>0,"Pontos normalizados após dividir por W. Compare cada valor com o limite indicado na linha.","Atenção: há W ≤ 0. A divisão por W não basta para decidir a visibilidade; o teste usa os planos de recorte.")) -> Pontos normalizados após dividir por W. Compare cada valor com o limite indicado na linha.
B14: Limite | C14: Condição | D14: A | E14: B | F14: C | G14: Fora (nº) | H14: Consequência
B15: Esquerdo | C15: X/W ≥ −1 | D15: =IF(Matrizes!$C$107<>"OK","—",Calculadora!G27) -> -0.078509226 | E15: =IF(Matrizes!$C$107<>"OK","—",Calculadora!H27) -> 0.15582392 | F15: =IF(Matrizes!$C$107<>"OK","—",Calculadora!I27) -> 0.02585892 | G15: =IF(Matrizes!$C$107<>"OK","—",IF(Matrizes!C116<-0.000000001,1,0)+IF(Matrizes!D116<-0.000000001,1,0)+IF(Matrizes!E116<-0.000000001,1,0)) -> 0 | H15: =IF(Matrizes!$C$107<>"OK","Aguardando dados",IF(G15=3,"Elimina o triângulo inteiro",IF(G15>0,"Exige recorte","Não corta o triângulo"))) -> Não corta o triângulo
B16: Direito | C16: X/W ≤ 1 | D16: =IF(Matrizes!$C$107<>"OK","—",Calculadora!G27) -> -0.078509226 | E16: =IF(Matrizes!$C$107<>"OK","—",Calculadora!H27) -> 0.15582392 | F16: =IF(Matrizes!$C$107<>"OK","—",Calculadora!I27) -> 0.02585892 | G16: =IF(Matrizes!$C$107<>"OK","—",IF(Matrizes!C117<-0.000000001,1,0)+IF(Matrizes!D117<-0.000000001,1,0)+IF(Matrizes!E117<-0.000000001,1,0)) -> 0 | H16: =IF(Matrizes!$C$107<>"OK","Aguardando dados",IF(G16=3,"Elimina o triângulo inteiro",IF(G16>0,"Exige recorte","Não corta o triângulo"))) -> Não corta o triângulo
B17: Inferior | C17: Y/W ≥ −1 | D17: =IF(Matrizes!$C$107<>"OK","—",Calculadora!G28) -> -0.32311658 | E17: =IF(Matrizes!$C$107<>"OK","—",Calculadora!H28) -> 0.74493147 | F17: =IF(Matrizes!$C$107<>"OK","—",Calculadora!I28) -> 0.065122949 | G17: =IF(Matrizes!$C$107<>"OK","—",IF(Matrizes!C118<-0.000000001,1,0)+IF(Matrizes!D118<-0.000000001,1,0)+IF(Matrizes!E118<-0.000000001,1,0)) -> 0 | H17: =IF(Matrizes!$C$107<>"OK","Aguardando dados",IF(G17=3,"Elimina o triângulo inteiro",IF(G17>0,"Exige recorte","Não corta o triângulo"))) -> Não corta o triângulo
B18: Superior | C18: Y/W ≤ 1 | D18: =IF(Matrizes!$C$107<>"OK","—",Calculadora!G28) -> -0.32311658 | E18: =IF(Matrizes!$C$107<>"OK","—",Calculadora!H28) -> 0.74493147 | F18: =IF(Matrizes!$C$107<>"OK","—",Calculadora!I28) -> 0.065122949 | G18: =IF(Matrizes!$C$107<>"OK","—",IF(Matrizes!C119<-0.000000001,1,0)+IF(Matrizes!D119<-0.000000001,1,0)+IF(Matrizes!E119<-0.000000001,1,0)) -> 0 | H18: =IF(Matrizes!$C$107<>"OK","Aguardando dados",IF(G18=3,"Elimina o triângulo inteiro",IF(G18>0,"Exige recorte","Não corta o triângulo"))) -> Não corta o triângulo
B19: Near | C19: Z/W ≥ −1 | D19: =IF(Matrizes!$C$107<>"OK","—",Calculadora!G29) -> 1.0297561 | E19: =IF(Matrizes!$C$107<>"OK","—",Calculadora!H29) -> 0.93272441 | F19: =IF(Matrizes!$C$107<>"OK","—",Calculadora!I29) -> 1.0232969 | G19: =IF(Matrizes!$C$107<>"OK","—",IF(Matrizes!C120<-0.000000001,1,0)+IF(Matrizes!D120<-0.000000001,1,0)+IF(Matrizes!E120<-0.000000001,1,0)) -> 0 | H19: =IF(Matrizes!$C$107<>"OK","Aguardando dados",IF(G19=3,"Elimina o triângulo inteiro",IF(G19>0,"Exige recorte","Não corta o triângulo"))) -> Não corta o triângulo
B20: Far | C20: Z/W ≤ 1 | D20: =IF(Matrizes!$C$107<>"OK","—",Calculadora!G29) -> 1.0297561 | E20: =IF(Matrizes!$C$107<>"OK","—",Calculadora!H29) -> 0.93272441 | F20: =IF(Matrizes!$C$107<>"OK","—",Calculadora!I29) -> 1.0232969 | G20: =IF(Matrizes!$C$107<>"OK","—",IF(Matrizes!C121<-0.000000001,1,0)+IF(Matrizes!D121<-0.000000001,1,0)+IF(Matrizes!E121<-0.000000001,1,0)) -> 2 | H20: =IF(Matrizes!$C$107<>"OK","Aguardando dados",IF(G20=3,"Elimina o triângulo inteiro",IF(G20>0,"Exige recorte","Não corta o triângulo"))) -> Exige recorte
B21: W normalizado | C21: W/W = 1 | D21: =IF(Matrizes!$C$107<>"OK","—",Calculadora!G30) -> 1 | E21: =IF(Matrizes!$C$107<>"OK","—",Calculadora!H30) -> 1 | F21: =IF(Matrizes!$C$107<>"OK","—",Calculadora!I30) -> 1 | G21: — | H21: Resultado da divisão
B22: X aparece duas vezes para testar esquerda e direita; Y, para baixo e cima; Z, para Near e Far. Vermelho destaca valores normalizados fora do intervalo da linha. Os valores são os mesmos da resposta na calculadora.
B25: Explicação completa de X, Y, Z e W
B26: =IF(Matrizes!$C$107<>"OK","Aguardando dados.",IF(MIN(Matrizes!G104:I104)<=0,"X: há vértices com W ≤ 0. Os valores após dividir por W não podem ser comparados isoladamente com −1 e 1 para decidir a visibilidade. Use o resultado do recorte acima.","X normalizado: "&"A = "&ROUND(D15,6)&IF(Matrizes!C116<-0.000000001," (à esquerda, fora)",IF(Matrizes!C117<-0.000000001," (à direita, fora)",IF(OR(ABS(Matrizes!C116)<=0.000000001,ABS(Matrizes!C117)<=0.000000001)," (na borda, permitido)"," (dentro)")))&"; "&"B = "&ROUND(E15,6)&IF(Matrizes!D116<-0.000000001," (à esquerda, fora)",IF(Matrizes!D117<-0.000000001," (à direita, fora)",IF(OR(ABS(Matrizes!D116)<=0.000000001,ABS(Matrizes!D117)<=0.000000001)," (na borda, permitido)"," (dentro)")))&"; "&"C = "&ROUND(F15,6)&IF(Matrizes!E116<-0.000000001," (à esquerda, fora)",IF(Matrizes!E117<-0.000000001," (à direita, fora)",IF(OR(ABS(Matrizes!E116)<=0.000000001,ABS(Matrizes!E117)<=0.000000001)," (na borda, permitido)"," (dentro)")))&". O intervalo permitido é de −1 a 1, incluindo os extremos.")) -> X normalizado: A = -0.078509 (dentro); B = 0.155824 (dentro); C = 0.025859 (dentro). O intervalo permitido é de −1 a 1, incluindo os extremos.
B29: =IF(Matrizes!$C$107<>"OK","Aguardando dados.",IF(MIN(Matrizes!G104:I104)<=0,"Y: há vértices com W ≤ 0. Os valores após dividir por W não podem ser comparados isoladamente com −1 e 1 para decidir a visibilidade. Use o resultado do recorte acima.","Y normalizado: "&"A = "&ROUND(D17,6)&IF(Matrizes!C118<-0.000000001," (abaixo, fora)",IF(Matrizes!C119<-0.000000001," (acima, fora)",IF(OR(ABS(Matrizes!C118)<=0.000000001,ABS(Matrizes!C119)<=0.000000001)," (na borda, permitido)"," (dentro)")))&"; "&"B = "&ROUND(E17,6)&IF(Matrizes!D118<-0.000000001," (abaixo, fora)",IF(Matrizes!D119<-0.000000001," (acima, fora)",IF(OR(ABS(Matrizes!D118)<=0.000000001,ABS(Matrizes!D119)<=0.000000001)," (na borda, permitido)"," (dentro)")))&"; "&"C = "&ROUND(F17,6)&IF(Matrizes!E118<-0.000000001," (abaixo, fora)",IF(Matrizes!E119<-0.000000001," (acima, fora)",IF(OR(ABS(Matrizes!E118)<=0.000000001,ABS(Matrizes!E119)<=0.000000001)," (na borda, permitido)"," (dentro)")))&". O intervalo permitido é de −1 a 1, incluindo os extremos.")) -> Y normalizado: A = -0.323117 (dentro); B = 0.744931 (dentro); C = 0.065123 (dentro). O intervalo permitido é de −1 a 1, incluindo os extremos.
B32: =IF(Matrizes!$C$107<>"OK","Aguardando dados.",IF(MIN(Matrizes!G104:I104)<=0,"Z: há vértices com W ≤ 0. Os valores após dividir por W não podem ser comparados isoladamente com −1 e 1 para decidir a visibilidade. Use o resultado do recorte acima.","Z normalizado: "&"A = "&ROUND(D19,6)&IF(Matrizes!C120<-0.000000001," (antes do Near, fora)",IF(Matrizes!C121<-0.000000001," (além do Far, fora)",IF(OR(ABS(Matrizes!C120)<=0.000000001,ABS(Matrizes!C121)<=0.000000001)," (na borda, permitido)"," (dentro)")))&"; "&"B = "&ROUND(E19,6)&IF(Matrizes!D120<-0.000000001," (antes do Near, fora)",IF(Matrizes!D121<-0.000000001," (além do Far, fora)",IF(OR(ABS(Matrizes!D120)<=0.000000001,ABS(Matrizes!D121)<=0.000000001)," (na borda, permitido)"," (dentro)")))&"; "&"C = "&ROUND(F19,6)&IF(Matrizes!E120<-0.000000001," (antes do Near, fora)",IF(Matrizes!E121<-0.000000001," (além do Far, fora)",IF(OR(ABS(Matrizes!E120)<=0.000000001,ABS(Matrizes!E121)<=0.000000001)," (na borda, permitido)"," (dentro)")))&". O intervalo permitido é de −1 a 1, incluindo os extremos.")) -> Z normalizado: A = 1.029756 (além do Far, fora); B = 0.932724 (dentro); C = 1.023297 (além do Far, fora). O intervalo permitido é de −1 a 1, incluindo os extremos.
B35: =IF(Matrizes!$C$107<>"OK","Aguardando dados.","W normalizado: "&"A = "&IF(ISNUMBER(D21),D21,"não definido")&"; "&"B = "&IF(ISNUMBER(E21),E21,"não definido")&"; "&"C = "&IF(ISNUMBER(F21),F21,"não definido")&". Quando a divisão é possível, W/W = 1. Esse 1 é a coordenada homogênea da resposta; não é um limite de visibilidade. É necessário conferir X, Y e Z e o W antes da divisão. Se o W original for zero, não é possível normalizar aquele vértice.") -> W normalizado: A = 1; B = 1; C = 1. Quando a divisão é possível, W/W = 1. Esse 1 é a coordenada homogênea da resposta; não é um limite de visibilidade. É necessário conferir X, Y e Z e o W antes da divisão. Se o W original for zero, não é possível normalizar aquele vértice.
B40: Um ponto só está dentro quando X, Y e Z respeitam seus limites ao mesmo tempo. Na borda também é permitido. A classificação considera o triângulo inteiro, inclusive arestas e interior. Oclusão por outro objeto e descarte de faces não são calculados. Tolerância no recorte: 10⁻⁹.
